2025-09-05 15:40:20 | [31mERROR[0m | __main__             | <module>       :197  | Error loading statistics: No columns to parse from file
C:\Users\Aman\Documents\Scheduling-System\ai-scheduling-agent\app.py:197
(<class 'pandas.errors.EmptyDataError'>, EmptyDataError('No columns to parse from file'), <traceback object at 0x00000298549E0640>)
Traceback (most recent call last):
  File "C:\Users\Aman\Documents\Scheduling-System\ai-scheduling-agent\app.py", line 167, in <module>
    patients_df = pd.read_csv(DATA_CONFIG["patients_file"])
  File "C:\Users\Aman\Documents\Scheduling-System\ai-scheduling-agent\.venv\Lib\site-packages\pandas\io\parsers\readers.py", line 1026, in read_csv
    return _read(filepath_or_buffer, kwds)
  File "C:\Users\Aman\Documents\Scheduling-System\ai-scheduling-agent\.venv\Lib\site-packages\pandas\io\parsers\readers.py", line 620, in _read
    parser = TextFileReader(filepath_or_buffer, **kwds)
  File "C:\Users\Aman\Documents\Scheduling-System\ai-scheduling-agent\.venv\Lib\site-packages\pandas\io\parsers\readers.py", line 1620, in __init__
    self._engine = self._make_engine(f, self.engine)
                   ~~~~~~~~~~~~~~~~~^^^^^^^^^^^^^^^^
  File "C:\Users\Aman\Documents\Scheduling-System\ai-scheduling-agent\.venv\Lib\site-packages\pandas\io\parsers\readers.py", line 1898, in _make_engine
    return mapping[engine](f, **self.options)
           ~~~~~~~~~~~~~~~^^^^^^^^^^^^^^^^^^^
  File "C:\Users\Aman\Documents\Scheduling-System\ai-scheduling-agent\.venv\Lib\site-packages\pandas\io\parsers\c_parser_wrapper.py", line 93, in __init__
    self._reader = parsers.TextReader(src, **kwds)
                   ~~~~~~~~~~~~~~~~~~^^^^^^^^^^^^^
  File "pandas/_libs/parsers.pyx", line 581, in pandas._libs.parsers.TextReader.__cinit__
pandas.errors.EmptyDataError: No columns to parse from file
2025-09-05 15:40:28 | [31mERROR[0m | __main__             | <module>       :197  | Error loading statistics: No columns to parse from file
C:\Users\Aman\Documents\Scheduling-System\ai-scheduling-agent\app.py:197
(<class 'pandas.errors.EmptyDataError'>, EmptyDataError('No columns to parse from file'), <traceback object at 0x0000029854959700>)
Traceback (most recent call last):
  File "C:\Users\Aman\Documents\Scheduling-System\ai-scheduling-agent\app.py", line 167, in <module>
    patients_df = pd.read_csv(DATA_CONFIG["patients_file"])
  File "C:\Users\Aman\Documents\Scheduling-System\ai-scheduling-agent\.venv\Lib\site-packages\pandas\io\parsers\readers.py", line 1026, in read_csv
    return _read(filepath_or_buffer, kwds)
  File "C:\Users\Aman\Documents\Scheduling-System\ai-scheduling-agent\.venv\Lib\site-packages\pandas\io\parsers\readers.py", line 620, in _read
    parser = TextFileReader(filepath_or_buffer, **kwds)
  File "C:\Users\Aman\Documents\Scheduling-System\ai-scheduling-agent\.venv\Lib\site-packages\pandas\io\parsers\readers.py", line 1620, in __init__
    self._engine = self._make_engine(f, self.engine)
                   ~~~~~~~~~~~~~~~~~^^^^^^^^^^^^^^^^
  File "C:\Users\Aman\Documents\Scheduling-System\ai-scheduling-agent\.venv\Lib\site-packages\pandas\io\parsers\readers.py", line 1898, in _make_engine
    return mapping[engine](f, **self.options)
           ~~~~~~~~~~~~~~~^^^^^^^^^^^^^^^^^^^
  File "C:\Users\Aman\Documents\Scheduling-System\ai-scheduling-agent\.venv\Lib\site-packages\pandas\io\parsers\c_parser_wrapper.py", line 93, in __init__
    self._reader = parsers.TextReader(src, **kwds)
                   ~~~~~~~~~~~~~~~~~~^^^^^^^^^^^^^
  File "pandas/_libs/parsers.pyx", line 581, in pandas._libs.parsers.TextReader.__cinit__
pandas.errors.EmptyDataError: No columns to parse from file
2025-09-05 15:40:29 | [31mERROR[0m | __main__             | simulate_error_scenarios:95   | Simulating file_not_found error
C:\Users\Aman\Documents\Scheduling-System\ai-scheduling-agent\demo_logging.py:95
(None, None, None)
NoneType: None
2025-09-05 15:40:29 | [31mERROR[0m | __main__             | simulate_error_scenarios:95   | Simulating database_connection error
C:\Users\Aman\Documents\Scheduling-System\ai-scheduling-agent\demo_logging.py:95
(None, None, None)
NoneType: None
2025-09-05 15:40:29 | [31mERROR[0m | __main__             | simulate_error_scenarios:95   | Simulating validation_error error
C:\Users\Aman\Documents\Scheduling-System\ai-scheduling-agent\demo_logging.py:95
(None, None, None)
NoneType: None
2025-09-05 15:40:29 | [31mERROR[0m | __main__             | simulate_error_scenarios:95   | Simulating permission_error error
C:\Users\Aman\Documents\Scheduling-System\ai-scheduling-agent\demo_logging.py:95
(None, None, None)
NoneType: None
2025-09-05 15:40:48 | [31mERROR[0m | __main__             | <module>       :197  | Error loading statistics: No columns to parse from file
C:\Users\Aman\Documents\Scheduling-System\ai-scheduling-agent\app.py:197
(<class 'pandas.errors.EmptyDataError'>, EmptyDataError('No columns to parse from file'), <traceback object at 0x00000298549D1940>)
Traceback (most recent call last):
  File "C:\Users\Aman\Documents\Scheduling-System\ai-scheduling-agent\app.py", line 167, in <module>
    patients_df = pd.read_csv(DATA_CONFIG["patients_file"])
  File "C:\Users\Aman\Documents\Scheduling-System\ai-scheduling-agent\.venv\Lib\site-packages\pandas\io\parsers\readers.py", line 1026, in read_csv
    return _read(filepath_or_buffer, kwds)
  File "C:\Users\Aman\Documents\Scheduling-System\ai-scheduling-agent\.venv\Lib\site-packages\pandas\io\parsers\readers.py", line 620, in _read
    parser = TextFileReader(filepath_or_buffer, **kwds)
  File "C:\Users\Aman\Documents\Scheduling-System\ai-scheduling-agent\.venv\Lib\site-packages\pandas\io\parsers\readers.py", line 1620, in __init__
    self._engine = self._make_engine(f, self.engine)
                   ~~~~~~~~~~~~~~~~~^^^^^^^^^^^^^^^^
  File "C:\Users\Aman\Documents\Scheduling-System\ai-scheduling-agent\.venv\Lib\site-packages\pandas\io\parsers\readers.py", line 1898, in _make_engine
    return mapping[engine](f, **self.options)
           ~~~~~~~~~~~~~~~^^^^^^^^^^^^^^^^^^^
  File "C:\Users\Aman\Documents\Scheduling-System\ai-scheduling-agent\.venv\Lib\site-packages\pandas\io\parsers\c_parser_wrapper.py", line 93, in __init__
    self._reader = parsers.TextReader(src, **kwds)
                   ~~~~~~~~~~~~~~~~~~^^^^^^^^^^^^^
  File "pandas/_libs/parsers.pyx", line 581, in pandas._libs.parsers.TextReader.__cinit__
pandas.errors.EmptyDataError: No columns to parse from file
2025-09-05 15:41:15 | [31mERROR[0m | __main__             | <module>       :197  | Error loading statistics: No columns to parse from file
C:\Users\Aman\Documents\Scheduling-System\ai-scheduling-agent\app.py:197
(<class 'pandas.errors.EmptyDataError'>, EmptyDataError('No columns to parse from file'), <traceback object at 0x0000029854A0FD80>)
Traceback (most recent call last):
  File "C:\Users\Aman\Documents\Scheduling-System\ai-scheduling-agent\app.py", line 167, in <module>
    patients_df = pd.read_csv(DATA_CONFIG["patients_file"])
  File "C:\Users\Aman\Documents\Scheduling-System\ai-scheduling-agent\.venv\Lib\site-packages\pandas\io\parsers\readers.py", line 1026, in read_csv
    return _read(filepath_or_buffer, kwds)
  File "C:\Users\Aman\Documents\Scheduling-System\ai-scheduling-agent\.venv\Lib\site-packages\pandas\io\parsers\readers.py", line 620, in _read
    parser = TextFileReader(filepath_or_buffer, **kwds)
  File "C:\Users\Aman\Documents\Scheduling-System\ai-scheduling-agent\.venv\Lib\site-packages\pandas\io\parsers\readers.py", line 1620, in __init__
    self._engine = self._make_engine(f, self.engine)
                   ~~~~~~~~~~~~~~~~~^^^^^^^^^^^^^^^^
  File "C:\Users\Aman\Documents\Scheduling-System\ai-scheduling-agent\.venv\Lib\site-packages\pandas\io\parsers\readers.py", line 1898, in _make_engine
    return mapping[engine](f, **self.options)
           ~~~~~~~~~~~~~~~^^^^^^^^^^^^^^^^^^^
  File "C:\Users\Aman\Documents\Scheduling-System\ai-scheduling-agent\.venv\Lib\site-packages\pandas\io\parsers\c_parser_wrapper.py", line 93, in __init__
    self._reader = parsers.TextReader(src, **kwds)
                   ~~~~~~~~~~~~~~~~~~^^^^^^^^^^^^^
  File "pandas/_libs/parsers.pyx", line 581, in pandas._libs.parsers.TextReader.__cinit__
pandas.errors.EmptyDataError: No columns to parse from file
2025-09-05 15:41:50 | [31mERROR[0m | __main__             | <module>       :197  | Error loading statistics: No columns to parse from file
C:\Users\Aman\Documents\Scheduling-System\ai-scheduling-agent\app.py:197
(<class 'pandas.errors.EmptyDataError'>, EmptyDataError('No columns to parse from file'), <traceback object at 0x00000298549F1680>)
Traceback (most recent call last):
  File "C:\Users\Aman\Documents\Scheduling-System\ai-scheduling-agent\app.py", line 167, in <module>
    patients_df = pd.read_csv(DATA_CONFIG["patients_file"])
  File "C:\Users\Aman\Documents\Scheduling-System\ai-scheduling-agent\.venv\Lib\site-packages\pandas\io\parsers\readers.py", line 1026, in read_csv
    return _read(filepath_or_buffer, kwds)
  File "C:\Users\Aman\Documents\Scheduling-System\ai-scheduling-agent\.venv\Lib\site-packages\pandas\io\parsers\readers.py", line 620, in _read
    parser = TextFileReader(filepath_or_buffer, **kwds)
  File "C:\Users\Aman\Documents\Scheduling-System\ai-scheduling-agent\.venv\Lib\site-packages\pandas\io\parsers\readers.py", line 1620, in __init__
    self._engine = self._make_engine(f, self.engine)
                   ~~~~~~~~~~~~~~~~~^^^^^^^^^^^^^^^^
  File "C:\Users\Aman\Documents\Scheduling-System\ai-scheduling-agent\.venv\Lib\site-packages\pandas\io\parsers\readers.py", line 1898, in _make_engine
    return mapping[engine](f, **self.options)
           ~~~~~~~~~~~~~~~^^^^^^^^^^^^^^^^^^^
  File "C:\Users\Aman\Documents\Scheduling-System\ai-scheduling-agent\.venv\Lib\site-packages\pandas\io\parsers\c_parser_wrapper.py", line 93, in __init__
    self._reader = parsers.TextReader(src, **kwds)
                   ~~~~~~~~~~~~~~~~~~^^^^^^^^^^^^^
  File "pandas/_libs/parsers.pyx", line 581, in pandas._libs.parsers.TextReader.__cinit__
pandas.errors.EmptyDataError: No columns to parse from file
2025-09-05 15:43:10 | [31mERROR[0m | __main__             | <module>       :197  | Error loading statistics: No columns to parse from file
C:\Users\Aman\Documents\Scheduling-System\ai-scheduling-agent\app.py:197
(<class 'pandas.errors.EmptyDataError'>, EmptyDataError('No columns to parse from file'), <traceback object at 0x0000029855D1A940>)
Traceback (most recent call last):
  File "C:\Users\Aman\Documents\Scheduling-System\ai-scheduling-agent\app.py", line 167, in <module>
    patients_df = pd.read_csv(DATA_CONFIG["patients_file"])
  File "C:\Users\Aman\Documents\Scheduling-System\ai-scheduling-agent\.venv\Lib\site-packages\pandas\io\parsers\readers.py", line 1026, in read_csv
    return _read(filepath_or_buffer, kwds)
  File "C:\Users\Aman\Documents\Scheduling-System\ai-scheduling-agent\.venv\Lib\site-packages\pandas\io\parsers\readers.py", line 620, in _read
    parser = TextFileReader(filepath_or_buffer, **kwds)
  File "C:\Users\Aman\Documents\Scheduling-System\ai-scheduling-agent\.venv\Lib\site-packages\pandas\io\parsers\readers.py", line 1620, in __init__
    self._engine = self._make_engine(f, self.engine)
                   ~~~~~~~~~~~~~~~~~^^^^^^^^^^^^^^^^
  File "C:\Users\Aman\Documents\Scheduling-System\ai-scheduling-agent\.venv\Lib\site-packages\pandas\io\parsers\readers.py", line 1898, in _make_engine
    return mapping[engine](f, **self.options)
           ~~~~~~~~~~~~~~~^^^^^^^^^^^^^^^^^^^
  File "C:\Users\Aman\Documents\Scheduling-System\ai-scheduling-agent\.venv\Lib\site-packages\pandas\io\parsers\c_parser_wrapper.py", line 93, in __init__
    self._reader = parsers.TextReader(src, **kwds)
                   ~~~~~~~~~~~~~~~~~~^^^^^^^^^^^^^
  File "pandas/_libs/parsers.pyx", line 581, in pandas._libs.parsers.TextReader.__cinit__
pandas.errors.EmptyDataError: No columns to parse from file
2025-09-05 15:43:10 | [31mERROR[0m | __main__             | <module>       :240  | Error reading logs: 'utf-8' codec can't decode byte 0x92 in position 2943: invalid start byte
C:\Users\Aman\Documents\Scheduling-System\ai-scheduling-agent\app.py:240
(<class 'UnicodeDecodeError'>, UnicodeDecodeError('utf-8', b'ers\\readers.py", line 1026, in read_csv\r\n    return _read(filepath_or_buffer, kwds)\r\n  File "C:\\Users\\Aman\\Documents\\Scheduling-System\\ai-scheduling-agent\\.venv\\Lib\\site-packages\\pandas\\io\\parsers\\readers.py", line 620, in _read\r\n    parser = TextFileReader(filepath_or_buffer, **kwds)\r\n  File "C:\\Users\\Aman\\Documents\\Scheduling-System\\ai-scheduling-agent\\.venv\\Lib\\site-packages\\pandas\\io\\parsers\\readers.py", line 1620, in __init__\r\n    self._engine = self._make_engine(f, self.engine)\r\n                   ~~~~~~~~~~~~~~~~~^^^^^^^^^^^^^^^^\r\n  File "C:\\Users\\Aman\\Documents\\Scheduling-System\\ai-scheduling-agent\\.venv\\Lib\\site-packages\\pandas\\io\\parsers\\readers.py", line 1898, in _make_engine\r\n    return mapping[engine](f, **self.options)\r\n           ~~~~~~~~~~~~~~~^^^^^^^^^^^^^^^^^^^\r\n  File "C:\\Users\\Aman\\Documents\\Scheduling-System\\ai-scheduling-agent\\.venv\\Lib\\site-packages\\pandas\\io\\parsers\\c_parser_wrapper.py", line 93, in __init__\r\n    self._reader = parsers.TextReader(src, **kwds)\r\n                   ~~~~~~~~~~~~~~~~~~^^^^^^^^^^^^^\r\n  File "pandas/_libs/parsers.pyx", line 581, in pandas._libs.parsers.TextReader.__cinit__\r\npandas.errors.EmptyDataError: No columns to parse from file\r\n2025-09-05 15:43:02 | \x1b[32mINFO\x1b[0m | __main__             | <module>       :24   | Initializing Streamlit application\r\n2025-09-05 15:43:02 | \x1b[32mINFO\x1b[0m | __main__             | <module>       :83   | User input received: gender: male, emergency name: Aditya, emergency contact: 8779500293 ...\r\n2025-09-05 15:43:02 | \x1b[32mINFO\x1b[0m | __main__             | log_agent_operation:195  | Operation: user_input | Details: {\r\n  "prompt": "gender: male, emergency name: Aditya, emergency contact: 8779500293 ",\r\n  "thread_id": "8a99098e-20af-4748-8c64-b9548a9f8499",\r\n  "timestamp": "2025-09-05T15:43:02.820339"\r\n}\r\n2025-09-05 15:43:02 | \x1b[32mINFO\x1b[0m | __main__             | <module>       :99   | Starting supervisor agent processing\r\n2025-09-05 15:43:05 | \x1b[32mINFO\x1b[0m | httpx                | _send_single_request:1025 | HTTP Request: POST https://api.openai.com/v1/chat/completions "HTTP/1.1 200 OK"\r\n2025-09-05 15:43:06 | \x1b[32mINFO\x1b[0m | httpx                | _send_single_request:1025 | HTTP Request: POST https://api.openai.com/v1/chat/completions "HTTP/1.1 200 OK"\r\n2025-09-05 15:43:08 | \x1b[32mINFO\x1b[0m | httpx                | _send_single_request:1025 | HTTP Request: POST https://api.openai.com/v1/chat/completions "HTTP/1.1 200 OK"\r\n2025-09-05 15:43:09 | \x1b[32mINFO\x1b[0m | httpx                | _send_single_request:1025 | HTTP Request: POST https://api.openai.com/v1/chat/completions "HTTP/1.1 200 OK"\r\n2025-09-05 15:43:10 | \x1b[32mINFO\x1b[0m | __main__             | <module>       :113  | Supervisor processing completed in 7.19 seconds\r\n2025-09-05 15:43:10 | \x1b[32mINFO\x1b[0m | __main__             | <module>       :117  | Final response generated: It appears there are still required details missing for your patient registration. I\x92ll need to clar...\r\n2025-09-05 15:43:10 | \x1b[32mINFO\x1b[0m | __main__             | <module>       :131  | Conversation history updated successfully\r\n2025-09-05 15:43:10 | \x1b[32mINFO\x1b[0m | __main__             | <module>       :163  | Loading system statistics\r\n2025-09-05 15:43:10 | \x1b[31mERROR\x1b[0m | __main__             | <module>       :197  | Error loading statistics: No columns to parse from file\r\nTraceback (most recent call last):\r\n  File "C:\\Users\\Aman\\Documents\\Scheduling-System\\ai-scheduling-agent\\app.py", line 167, in <module>\r\n    patients_df = pd.read_csv(DATA_CONFIG["patients_file"])\r\n  File "C:\\Users\\Aman\\Documents\\Scheduling-System\\ai-scheduling-agent\\.venv\\Lib\\site-packages\\pandas\\io\\parsers\\readers.py", line 1026, in read_csv\r\n    return _read(filepath_or_buffer, kwds)\r\n  File "C:\\Users\\Aman\\Documents\\Scheduling-System\\ai-scheduling-agent\\.venv\\Lib\\site-packages\\pandas\\io\\parsers\\readers.py", line 620, in _read\r\n    parser = TextFileReader(filepath_or_buffer, **kwds)\r\n  File "C:\\Users\\Aman\\Documents\\Scheduling-System\\ai-scheduling-agent\\.venv\\Lib\\site-packages\\pandas\\io\\parsers\\readers.py", line 1620, in __init__\r\n    self._engine = self._make_engine(f, self.engine)\r\n                   ~~~~~~~~~~~~~~~~~^^^^^^^^^^^^^^^^\r\n  File "C:\\Users\\Aman\\Documents\\Scheduling-System\\ai-scheduling-agent\\.venv\\Lib\\site-packages\\pandas\\io\\parsers\\readers.py", line 1898, in _make_engine\r\n    return mapping[engine](f, **self.options)\r\n           ~~~~~~~~~~~~~~~^^^^^^^^^^^^^^^^^^^\r\n  File "C:\\Users\\Aman\\Documents\\Scheduling-System\\ai-scheduling-agent\\.venv\\Lib\\site-packages\\pandas\\io\\parsers\\c_parser_wrapper.py", line 93, in __init__\r\n    self._reader = parsers.TextReader(src, **kwds)\r\n                   ~~~~~~~~~~~~~~~~~~^^^^^^^^^^^^^\r\n  File "pandas/_libs/parsers.pyx", line 581, in pandas._libs.parsers.TextReader.__cinit__\r\npandas.errors.EmptyDataError: No columns to parse from file\r\n', 2943, 2944, 'invalid start byte'), <traceback object at 0x00000298549F8200>)
Traceback (most recent call last):
  File "C:\Users\Aman\Documents\Scheduling-System\ai-scheduling-agent\app.py", line 221, in <module>
    lines = f.readlines()
  File "<frozen codecs>", line 325, in decode
UnicodeDecodeError: 'utf-8' codec can't decode byte 0x92 in position 2943: invalid start byte
2025-09-05 15:43:36 | [31mERROR[0m | __main__             | <module>       :197  | Error loading statistics: No columns to parse from file
C:\Users\Aman\Documents\Scheduling-System\ai-scheduling-agent\app.py:197
(<class 'pandas.errors.EmptyDataError'>, EmptyDataError('No columns to parse from file'), <traceback object at 0x000002985486A7C0>)
Traceback (most recent call last):
  File "C:\Users\Aman\Documents\Scheduling-System\ai-scheduling-agent\app.py", line 167, in <module>
    patients_df = pd.read_csv(DATA_CONFIG["patients_file"])
  File "C:\Users\Aman\Documents\Scheduling-System\ai-scheduling-agent\.venv\Lib\site-packages\pandas\io\parsers\readers.py", line 1026, in read_csv
    return _read(filepath_or_buffer, kwds)
  File "C:\Users\Aman\Documents\Scheduling-System\ai-scheduling-agent\.venv\Lib\site-packages\pandas\io\parsers\readers.py", line 620, in _read
    parser = TextFileReader(filepath_or_buffer, **kwds)
  File "C:\Users\Aman\Documents\Scheduling-System\ai-scheduling-agent\.venv\Lib\site-packages\pandas\io\parsers\readers.py", line 1620, in __init__
    self._engine = self._make_engine(f, self.engine)
                   ~~~~~~~~~~~~~~~~~^^^^^^^^^^^^^^^^
  File "C:\Users\Aman\Documents\Scheduling-System\ai-scheduling-agent\.venv\Lib\site-packages\pandas\io\parsers\readers.py", line 1898, in _make_engine
    return mapping[engine](f, **self.options)
           ~~~~~~~~~~~~~~~^^^^^^^^^^^^^^^^^^^
  File "C:\Users\Aman\Documents\Scheduling-System\ai-scheduling-agent\.venv\Lib\site-packages\pandas\io\parsers\c_parser_wrapper.py", line 93, in __init__
    self._reader = parsers.TextReader(src, **kwds)
                   ~~~~~~~~~~~~~~~~~~^^^^^^^^^^^^^
  File "pandas/_libs/parsers.pyx", line 581, in pandas._libs.parsers.TextReader.__cinit__
pandas.errors.EmptyDataError: No columns to parse from file
2025-09-05 15:43:36 | [31mERROR[0m | __main__             | <module>       :240  | Error reading logs: 'utf-8' codec can't decode byte 0x92 in position 2943: invalid start byte
C:\Users\Aman\Documents\Scheduling-System\ai-scheduling-agent\app.py:240
(<class 'UnicodeDecodeError'>, UnicodeDecodeError('utf-8', b'ers\\readers.py", line 1026, in read_csv\r\n    return _read(filepath_or_buffer, kwds)\r\n  File "C:\\Users\\Aman\\Documents\\Scheduling-System\\ai-scheduling-agent\\.venv\\Lib\\site-packages\\pandas\\io\\parsers\\readers.py", line 620, in _read\r\n    parser = TextFileReader(filepath_or_buffer, **kwds)\r\n  File "C:\\Users\\Aman\\Documents\\Scheduling-System\\ai-scheduling-agent\\.venv\\Lib\\site-packages\\pandas\\io\\parsers\\readers.py", line 1620, in __init__\r\n    self._engine = self._make_engine(f, self.engine)\r\n                   ~~~~~~~~~~~~~~~~~^^^^^^^^^^^^^^^^\r\n  File "C:\\Users\\Aman\\Documents\\Scheduling-System\\ai-scheduling-agent\\.venv\\Lib\\site-packages\\pandas\\io\\parsers\\readers.py", line 1898, in _make_engine\r\n    return mapping[engine](f, **self.options)\r\n           ~~~~~~~~~~~~~~~^^^^^^^^^^^^^^^^^^^\r\n  File "C:\\Users\\Aman\\Documents\\Scheduling-System\\ai-scheduling-agent\\.venv\\Lib\\site-packages\\pandas\\io\\parsers\\c_parser_wrapper.py", line 93, in __init__\r\n    self._reader = parsers.TextReader(src, **kwds)\r\n                   ~~~~~~~~~~~~~~~~~~^^^^^^^^^^^^^\r\n  File "pandas/_libs/parsers.pyx", line 581, in pandas._libs.parsers.TextReader.__cinit__\r\npandas.errors.EmptyDataError: No columns to parse from file\r\n2025-09-05 15:43:02 | \x1b[32mINFO\x1b[0m | __main__             | <module>       :24   | Initializing Streamlit application\r\n2025-09-05 15:43:02 | \x1b[32mINFO\x1b[0m | __main__             | <module>       :83   | User input received: gender: male, emergency name: Aditya, emergency contact: 8779500293 ...\r\n2025-09-05 15:43:02 | \x1b[32mINFO\x1b[0m | __main__             | log_agent_operation:195  | Operation: user_input | Details: {\r\n  "prompt": "gender: male, emergency name: Aditya, emergency contact: 8779500293 ",\r\n  "thread_id": "8a99098e-20af-4748-8c64-b9548a9f8499",\r\n  "timestamp": "2025-09-05T15:43:02.820339"\r\n}\r\n2025-09-05 15:43:02 | \x1b[32mINFO\x1b[0m | __main__             | <module>       :99   | Starting supervisor agent processing\r\n2025-09-05 15:43:05 | \x1b[32mINFO\x1b[0m | httpx                | _send_single_request:1025 | HTTP Request: POST https://api.openai.com/v1/chat/completions "HTTP/1.1 200 OK"\r\n2025-09-05 15:43:06 | \x1b[32mINFO\x1b[0m | httpx                | _send_single_request:1025 | HTTP Request: POST https://api.openai.com/v1/chat/completions "HTTP/1.1 200 OK"\r\n2025-09-05 15:43:08 | \x1b[32mINFO\x1b[0m | httpx                | _send_single_request:1025 | HTTP Request: POST https://api.openai.com/v1/chat/completions "HTTP/1.1 200 OK"\r\n2025-09-05 15:43:09 | \x1b[32mINFO\x1b[0m | httpx                | _send_single_request:1025 | HTTP Request: POST https://api.openai.com/v1/chat/completions "HTTP/1.1 200 OK"\r\n2025-09-05 15:43:10 | \x1b[32mINFO\x1b[0m | __main__             | <module>       :113  | Supervisor processing completed in 7.19 seconds\r\n2025-09-05 15:43:10 | \x1b[32mINFO\x1b[0m | __main__             | <module>       :117  | Final response generated: It appears there are still required details missing for your patient registration. I\x92ll need to clar...\r\n2025-09-05 15:43:10 | \x1b[32mINFO\x1b[0m | __main__             | <module>       :131  | Conversation history updated successfully\r\n2025-09-05 15:43:10 | \x1b[32mINFO\x1b[0m | __main__             | <module>       :163  | Loading system statistics\r\n2025-09-05 15:43:10 | \x1b[31mERROR\x1b[0m | __main__             | <module>       :197  | Error loading statistics: No columns to parse from file\r\nTraceback (most recent call last):\r\n  File "C:\\Users\\Aman\\Documents\\Scheduling-System\\ai-scheduling-agent\\app.py", line 167, in <module>\r\n    patients_df = pd.read_csv(DATA_CONFIG["patients_file"])\r\n  File "C:\\Users\\Aman\\Documents\\Scheduling-System\\ai-scheduling-agent\\.venv\\Lib\\site-packages\\pandas\\io\\parsers\\readers.py", line 1026, in read_csv\r\n    return _read(filepath_or_buffer, kwds)\r\n  File "C:\\Users\\Aman\\Documents\\Scheduling-System\\ai-scheduling-agent\\.venv\\Lib\\site-packages\\pandas\\io\\parsers\\readers.py", line 620, in _read\r\n    parser = TextFileReader(filepath_or_buffer, **kwds)\r\n  File "C:\\Users\\Aman\\Documents\\Scheduling-System\\ai-scheduling-agent\\.venv\\Lib\\site-packages\\pandas\\io\\parsers\\readers.py", line 1620, in __init__\r\n    self._engine = self._make_engine(f, self.engine)\r\n                   ~~~~~~~~~~~~~~~~~^^^^^^^^^^^^^^^^\r\n  File "C:\\Users\\Aman\\Documents\\Scheduling-System\\ai-scheduling-agent\\.venv\\Lib\\site-packages\\pandas\\io\\parsers\\readers.py", line 1898, in _make_engine\r\n    return mapping[engine](f, **self.options)\r\n           ~~~~~~~~~~~~~~~^^^^^^^^^^^^^^^^^^^\r\n  File "C:\\Users\\Aman\\Documents\\Scheduling-System\\ai-scheduling-agent\\.venv\\Lib\\site-packages\\pandas\\io\\parsers\\c_parser_wrapper.py", line 93, in __init__\r\n    self._reader = parsers.TextReader(src, **kwds)\r\n                   ~~~~~~~~~~~~~~~~~~^^^^^^^^^^^^^\r\n  File "pandas/_libs/parsers.pyx", line 581, in pandas._libs.parsers.TextReader.__cinit__\r\npandas.errors.EmptyDataError: No columns to parse from file\r\n2025-09-05 15:43:10 | \x1b[31mERROR\x1b[0m | __main__             | <module>       :240  | Error reading logs: \'utf-8\' codec can\'t decode byte 0x92 in position 2943: invalid start byte\r\nTraceback (most recent call last):\r\n  File "C:\\Users\\Aman\\Documents\\Scheduling-System\\ai-scheduling-agent\\app.py", line 221, in <module>\r\n    lines = f.readlines()\r\n  File "<frozen codecs>", line 325, in decode\r\nUnicodeDecodeError: \'utf-8\' codec can\'t decode byte 0x92 in position 2943: invalid start byte\r\n2025-09-05 15:43:31 | \x1b[32mINFO\x1b[0m | __main__             | <module>       :24   | Initializing Streamlit application\r\n2025-09-05 15:43:31 | \x1b[32mINFO\x1b[0m | __main__             | <module>       :83   | User input received: book the appointment...\r\n2025-09-05 15:43:31 | \x1b[32mINFO\x1b[0m | __main__             | log_agent_operation:195  | Operation: user_input | Details: {\r\n  "prompt": "book the appointment",\r\n  "thread_id": "8a99098e-20af-4748-8c64-b9548a9f8499",\r\n  "timestamp": "2025-09-05T15:43:31.237753"\r\n}\r\n2025-09-05 15:43:31 | \x1b[32mINFO\x1b[0m | __main__             | <module>       :99   | Starting supervisor agent processing\r\n2025-09-05 15:43:33 | \x1b[32mINFO\x1b[0m | httpx                | _send_single_request:1025 | HTTP Request: POST https://api.openai.com/v1/chat/completions "HTTP/1.1 200 OK"\r\n2025-09-05 15:43:34 | \x1b[32mINFO\x1b[0m | httpx                | _send_single_request:1025 | HTTP Request: POST https://api.openai.com/v1/chat/completions "HTTP/1.1 200 OK"\r\n2025-09-05 15:43:36 | \x1b[32mINFO\x1b[0m | httpx                | _send_single_request:1025 | HTTP Request: POST https://api.openai.com/v1/chat/completions "HTTP/1.1 200 OK"\r\n2025-09-05 15:43:36 | \x1b[32mINFO\x1b[0m | __main__             | <module>       :113  | Supervisor processing completed in 5.05 seconds\r\n2025-09-05 15:43:36 | \x1b[32mINFO\x1b[0m | __main__             | <module>       :117  | Final response generated: Could you please let me know if you have a preferred doctor or a preferred date and time for your ap...\r\n2025-09-05 15:43:36 | \x1b[32mINFO\x1b[0m | __main__             | <module>       :131  | Conversation history updated successfully\r\n2025-09-05 15:43:36 | \x1b[32mINFO\x1b[0m | __main__             | <module>       :163  | Loading system statistics\r\n2025-09-05 15:43:36 | \x1b[31mERROR\x1b[0m | __main__             | <module>       :197  | Error loading statistics: No columns to parse from file\r\nTraceback (most recent call last):\r\n  File "C:\\Users\\Aman\\Documents\\Scheduling-System\\ai-scheduling-agent\\app.py", line 167, in <module>\r\n    patients_df = pd.read_csv(DATA_CONFIG["patients_file"])\r\n  File "C:\\Users\\Aman\\Documents\\Scheduling-System\\ai-scheduling-agent\\.venv\\Lib\\site-packages\\pandas\\io\\parsers\\readers.py", line 1026, in read_csv\r\n    return _read(filepath_or_buffer, kwds)\r\n  File "C:\\Users\\Aman\\Documents\\Scheduling-System\\ai-scheduling-agent\\.venv\\Lib\\site-packages\\pandas\\io\\parsers\\readers.py", line 620, in _read\r\n    parser = TextFileReader(filepath_or_buffer, **kwds)\r\n  File "C:\\Users\\Aman\\Documents\\Scheduling-System\\ai-scheduling-agent\\.venv\\Lib\\site-packages\\pandas\\io\\parsers\\readers.py", line 1620, in __init__\r\n    self._engine = self._make_engine(f, self.engine)\r\n                   ~~~~~~~~~~~~~~~~~^^^^^^^^^^^^^^^^\r\n  File "C:\\Users\\Aman\\Documents\\Scheduling-System\\ai-scheduling-agent\\.venv\\Lib\\site-packages\\pandas\\io\\parsers\\readers.py", ', 2943, 2944, 'invalid start byte'), <traceback object at 0x00000298549AB740>)
Traceback (most recent call last):
  File "C:\Users\Aman\Documents\Scheduling-System\ai-scheduling-agent\app.py", line 221, in <module>
    lines = f.readlines()
  File "<frozen codecs>", line 325, in decode
UnicodeDecodeError: 'utf-8' codec can't decode byte 0x92 in position 2943: invalid start byte
2025-09-05 15:51:38 | [31mERROR[0m | __main__             | simulate_error_scenarios:95   | Simulating file_not_found error
C:\Users\Aman\Documents\Scheduling-System\ai-scheduling-agent\demo_logging.py:95
(None, None, None)
NoneType: None
2025-09-05 15:51:38 | [31mERROR[0m | __main__             | simulate_error_scenarios:95   | Simulating database_connection error
C:\Users\Aman\Documents\Scheduling-System\ai-scheduling-agent\demo_logging.py:95
(None, None, None)
NoneType: None
2025-09-05 15:51:38 | [31mERROR[0m | __main__             | simulate_error_scenarios:95   | Simulating validation_error error
C:\Users\Aman\Documents\Scheduling-System\ai-scheduling-agent\demo_logging.py:95
(None, None, None)
NoneType: None
2025-09-05 15:51:38 | [31mERROR[0m | __main__             | simulate_error_scenarios:95   | Simulating permission_error error
C:\Users\Aman\Documents\Scheduling-System\ai-scheduling-agent\demo_logging.py:95
(None, None, None)
NoneType: None
2025-09-05 15:52:05 | [31mERROR[0m | __main__             | <module>       :240  | Error reading logs: 'utf-8' codec can't decode byte 0x92 in position 2943: invalid start byte
C:\Users\Aman\Documents\Scheduling-System\ai-scheduling-agent\app.py:240
(<class 'UnicodeDecodeError'>, UnicodeDecodeError('utf-8', b'ers\\readers.py", line 1026, in read_csv\r\n    return _read(filepath_or_buffer, kwds)\r\n  File "C:\\Users\\Aman\\Documents\\Scheduling-System\\ai-scheduling-agent\\.venv\\Lib\\site-packages\\pandas\\io\\parsers\\readers.py", line 620, in _read\r\n    parser = TextFileReader(filepath_or_buffer, **kwds)\r\n  File "C:\\Users\\Aman\\Documents\\Scheduling-System\\ai-scheduling-agent\\.venv\\Lib\\site-packages\\pandas\\io\\parsers\\readers.py", line 1620, in __init__\r\n    self._engine = self._make_engine(f, self.engine)\r\n                   ~~~~~~~~~~~~~~~~~^^^^^^^^^^^^^^^^\r\n  File "C:\\Users\\Aman\\Documents\\Scheduling-System\\ai-scheduling-agent\\.venv\\Lib\\site-packages\\pandas\\io\\parsers\\readers.py", line 1898, in _make_engine\r\n    return mapping[engine](f, **self.options)\r\n           ~~~~~~~~~~~~~~~^^^^^^^^^^^^^^^^^^^\r\n  File "C:\\Users\\Aman\\Documents\\Scheduling-System\\ai-scheduling-agent\\.venv\\Lib\\site-packages\\pandas\\io\\parsers\\c_parser_wrapper.py", line 93, in __init__\r\n    self._reader = parsers.TextReader(src, **kwds)\r\n                   ~~~~~~~~~~~~~~~~~~^^^^^^^^^^^^^\r\n  File "pandas/_libs/parsers.pyx", line 581, in pandas._libs.parsers.TextReader.__cinit__\r\npandas.errors.EmptyDataError: No columns to parse from file\r\n2025-09-05 15:43:02 | \x1b[32mINFO\x1b[0m | __main__             | <module>       :24   | Initializing Streamlit application\r\n2025-09-05 15:43:02 | \x1b[32mINFO\x1b[0m | __main__             | <module>       :83   | User input received: gender: male, emergency name: Aditya, emergency contact: 8779500293 ...\r\n2025-09-05 15:43:02 | \x1b[32mINFO\x1b[0m | __main__             | log_agent_operation:195  | Operation: user_input | Details: {\r\n  "prompt": "gender: male, emergency name: Aditya, emergency contact: 8779500293 ",\r\n  "thread_id": "8a99098e-20af-4748-8c64-b9548a9f8499",\r\n  "timestamp": "2025-09-05T15:43:02.820339"\r\n}\r\n2025-09-05 15:43:02 | \x1b[32mINFO\x1b[0m | __main__             | <module>       :99   | Starting supervisor agent processing\r\n2025-09-05 15:43:05 | \x1b[32mINFO\x1b[0m | httpx                | _send_single_request:1025 | HTTP Request: POST https://api.openai.com/v1/chat/completions "HTTP/1.1 200 OK"\r\n2025-09-05 15:43:06 | \x1b[32mINFO\x1b[0m | httpx                | _send_single_request:1025 | HTTP Request: POST https://api.openai.com/v1/chat/completions "HTTP/1.1 200 OK"\r\n2025-09-05 15:43:08 | \x1b[32mINFO\x1b[0m | httpx                | _send_single_request:1025 | HTTP Request: POST https://api.openai.com/v1/chat/completions "HTTP/1.1 200 OK"\r\n2025-09-05 15:43:09 | \x1b[32mINFO\x1b[0m | httpx                | _send_single_request:1025 | HTTP Request: POST https://api.openai.com/v1/chat/completions "HTTP/1.1 200 OK"\r\n2025-09-05 15:43:10 | \x1b[32mINFO\x1b[0m | __main__             | <module>       :113  | Supervisor processing completed in 7.19 seconds\r\n2025-09-05 15:43:10 | \x1b[32mINFO\x1b[0m | __main__             | <module>       :117  | Final response generated: It appears there are still required details missing for your patient registration. I\x92ll need to clar...\r\n2025-09-05 15:43:10 | \x1b[32mINFO\x1b[0m | __main__             | <module>       :131  | Conversation history updated successfully\r\n2025-09-05 15:43:10 | \x1b[32mINFO\x1b[0m | __main__             | <module>       :163  | Loading system statistics\r\n2025-09-05 15:43:10 | \x1b[31mERROR\x1b[0m | __main__             | <module>       :197  | Error loading statistics: No columns to parse from file\r\nTraceback (most recent call last):\r\n  File "C:\\Users\\Aman\\Documents\\Scheduling-System\\ai-scheduling-agent\\app.py", line 167, in <module>\r\n    patients_df = pd.read_csv(DATA_CONFIG["patients_file"])\r\n  File "C:\\Users\\Aman\\Documents\\Scheduling-System\\ai-scheduling-agent\\.venv\\Lib\\site-packages\\pandas\\io\\parsers\\readers.py", line 1026, in read_csv\r\n    return _read(filepath_or_buffer, kwds)\r\n  File "C:\\Users\\Aman\\Documents\\Scheduling-System\\ai-scheduling-agent\\.venv\\Lib\\site-packages\\pandas\\io\\parsers\\readers.py", line 620, in _read\r\n    parser = TextFileReader(filepath_or_buffer, **kwds)\r\n  File "C:\\Users\\Aman\\Documents\\Scheduling-System\\ai-scheduling-agent\\.venv\\Lib\\site-packages\\pandas\\io\\parsers\\readers.py", line 1620, in __init__\r\n    self._engine = self._make_engine(f, self.engine)\r\n                   ~~~~~~~~~~~~~~~~~^^^^^^^^^^^^^^^^\r\n  File "C:\\Users\\Aman\\Documents\\Scheduling-System\\ai-scheduling-agent\\.venv\\Lib\\site-packages\\pandas\\io\\parsers\\readers.py", line 1898, in _make_engine\r\n    return mapping[engine](f, **self.options)\r\n           ~~~~~~~~~~~~~~~^^^^^^^^^^^^^^^^^^^\r\n  File "C:\\Users\\Aman\\Documents\\Scheduling-System\\ai-scheduling-agent\\.venv\\Lib\\site-packages\\pandas\\io\\parsers\\c_parser_wrapper.py", line 93, in __init__\r\n    self._reader = parsers.TextReader(src, **kwds)\r\n                   ~~~~~~~~~~~~~~~~~~^^^^^^^^^^^^^\r\n  File "pandas/_libs/parsers.pyx", line 581, in pandas._libs.parsers.TextReader.__cinit__\r\npandas.errors.EmptyDataError: No columns to parse from file\r\n2025-09-05 15:43:10 | \x1b[31mERROR\x1b[0m | __main__             | <module>       :240  | Error reading logs: \'utf-8\' codec can\'t decode byte 0x92 in position 2943: invalid start byte\r\nTraceback (most recent call last):\r\n  File "C:\\Users\\Aman\\Documents\\Scheduling-System\\ai-scheduling-agent\\app.py", line 221, in <module>\r\n    lines = f.readlines()\r\n  File "<frozen codecs>", line 325, in decode\r\nUnicodeDecodeError: \'utf-8\' codec can\'t decode byte 0x92 in position 2943: invalid start byte\r\n2025-09-05 15:43:31 | \x1b[32mINFO\x1b[0m | __main__             | <module>       :24   | Initializing Streamlit application\r\n2025-09-05 15:43:31 | \x1b[32mINFO\x1b[0m | __main__             | <module>       :83   | User input received: book the appointment...\r\n2025-09-05 15:43:31 | \x1b[32mINFO\x1b[0m | __main__             | log_agent_operation:195  | Operation: user_input | Details: {\r\n  "prompt": "book the appointment",\r\n  "thread_id": "8a99098e-20af-4748-8c64-b9548a9f8499",\r\n  "timestamp": "2025-09-05T15:43:31.237753"\r\n}\r\n2025-09-05 15:43:31 | \x1b[32mINFO\x1b[0m | __main__             | <module>       :99   | Starting supervisor agent processing\r\n2025-09-05 15:43:33 | \x1b[32mINFO\x1b[0m | httpx                | _send_single_request:1025 | HTTP Request: POST https://api.openai.com/v1/chat/completions "HTTP/1.1 200 OK"\r\n2025-09-05 15:43:34 | \x1b[32mINFO\x1b[0m | httpx                | _send_single_request:1025 | HTTP Request: POST https://api.openai.com/v1/chat/completions "HTTP/1.1 200 OK"\r\n2025-09-05 15:43:36 | \x1b[32mINFO\x1b[0m | httpx                | _send_single_request:1025 | HTTP Request: POST https://api.openai.com/v1/chat/completions "HTTP/1.1 200 OK"\r\n2025-09-05 15:43:36 | \x1b[32mINFO\x1b[0m | __main__             | <module>       :113  | Supervisor processing completed in 5.05 seconds\r\n2025-09-05 15:43:36 | \x1b[32mINFO\x1b[0m | __main__             | <module>       :117  | Final response generated: Could you please let me know if you have a preferred doctor or a preferred date and time for your ap...\r\n2025-09-05 15:43:36 | \x1b[32mINFO\x1b[0m | __main__             | <module>       :131  | Conversation history updated successfully\r\n2025-09-05 15:43:36 | \x1b[32mINFO\x1b[0m | __main__             | <module>       :163  | Loading system statistics\r\n2025-09-05 15:43:36 | \x1b[31mERROR\x1b[0m | __main__             | <module>       :197  | Error loading statistics: No columns to parse from file\r\nTraceback (most recent call last):\r\n  File "C:\\Users\\Aman\\Documents\\Scheduling-System\\ai-scheduling-agent\\app.py", line 167, in <module>\r\n    patients_df = pd.read_csv(DATA_CONFIG["patients_file"])\r\n  File "C:\\Users\\Aman\\Documents\\Scheduling-System\\ai-scheduling-agent\\.venv\\Lib\\site-packages\\pandas\\io\\parsers\\readers.py", line 1026, in read_csv\r\n    return _read(filepath_or_buffer, kwds)\r\n  File "C:\\Users\\Aman\\Documents\\Scheduling-System\\ai-scheduling-agent\\.venv\\Lib\\site-packages\\pandas\\io\\parsers\\readers.py", line 620, in _read\r\n    parser = TextFileReader(filepath_or_buffer, **kwds)\r\n  File "C:\\Users\\Aman\\Documents\\Scheduling-System\\ai-scheduling-agent\\.venv\\Lib\\site-packages\\pandas\\io\\parsers\\readers.py", line 1620, in __init__\r\n    self._engine = self._make_engine(f, self.engine)\r\n                   ~~~~~~~~~~~~~~~~~^^^^^^^^^^^^^^^^\r\n  File "C:\\Users\\Aman\\Documents\\Scheduling-System\\ai-scheduling-agent\\.venv\\Lib\\site-packages\\pandas\\io\\parsers\\readers.py", ', 2943, 2944, 'invalid start byte'), <traceback object at 0x0000024BF2716F80>)
Traceback (most recent call last):
  File "C:\Users\Aman\Documents\Scheduling-System\ai-scheduling-agent\app.py", line 221, in <module>
    lines = f.readlines()
  File "<frozen codecs>", line 325, in decode
UnicodeDecodeError: 'utf-8' codec can't decode byte 0x92 in position 2943: invalid start byte
2025-09-05 15:52:38 | [31mERROR[0m | __main__             | <module>       :240  | Error reading logs: 'utf-8' codec can't decode byte 0x92 in position 2943: invalid start byte
C:\Users\Aman\Documents\Scheduling-System\ai-scheduling-agent\app.py:240
(<class 'UnicodeDecodeError'>, UnicodeDecodeError('utf-8', b'ers\\readers.py", line 1026, in read_csv\r\n    return _read(filepath_or_buffer, kwds)\r\n  File "C:\\Users\\Aman\\Documents\\Scheduling-System\\ai-scheduling-agent\\.venv\\Lib\\site-packages\\pandas\\io\\parsers\\readers.py", line 620, in _read\r\n    parser = TextFileReader(filepath_or_buffer, **kwds)\r\n  File "C:\\Users\\Aman\\Documents\\Scheduling-System\\ai-scheduling-agent\\.venv\\Lib\\site-packages\\pandas\\io\\parsers\\readers.py", line 1620, in __init__\r\n    self._engine = self._make_engine(f, self.engine)\r\n                   ~~~~~~~~~~~~~~~~~^^^^^^^^^^^^^^^^\r\n  File "C:\\Users\\Aman\\Documents\\Scheduling-System\\ai-scheduling-agent\\.venv\\Lib\\site-packages\\pandas\\io\\parsers\\readers.py", line 1898, in _make_engine\r\n    return mapping[engine](f, **self.options)\r\n           ~~~~~~~~~~~~~~~^^^^^^^^^^^^^^^^^^^\r\n  File "C:\\Users\\Aman\\Documents\\Scheduling-System\\ai-scheduling-agent\\.venv\\Lib\\site-packages\\pandas\\io\\parsers\\c_parser_wrapper.py", line 93, in __init__\r\n    self._reader = parsers.TextReader(src, **kwds)\r\n                   ~~~~~~~~~~~~~~~~~~^^^^^^^^^^^^^\r\n  File "pandas/_libs/parsers.pyx", line 581, in pandas._libs.parsers.TextReader.__cinit__\r\npandas.errors.EmptyDataError: No columns to parse from file\r\n2025-09-05 15:43:02 | \x1b[32mINFO\x1b[0m | __main__             | <module>       :24   | Initializing Streamlit application\r\n2025-09-05 15:43:02 | \x1b[32mINFO\x1b[0m | __main__             | <module>       :83   | User input received: gender: male, emergency name: Aditya, emergency contact: 8779500293 ...\r\n2025-09-05 15:43:02 | \x1b[32mINFO\x1b[0m | __main__             | log_agent_operation:195  | Operation: user_input | Details: {\r\n  "prompt": "gender: male, emergency name: Aditya, emergency contact: 8779500293 ",\r\n  "thread_id": "8a99098e-20af-4748-8c64-b9548a9f8499",\r\n  "timestamp": "2025-09-05T15:43:02.820339"\r\n}\r\n2025-09-05 15:43:02 | \x1b[32mINFO\x1b[0m | __main__             | <module>       :99   | Starting supervisor agent processing\r\n2025-09-05 15:43:05 | \x1b[32mINFO\x1b[0m | httpx                | _send_single_request:1025 | HTTP Request: POST https://api.openai.com/v1/chat/completions "HTTP/1.1 200 OK"\r\n2025-09-05 15:43:06 | \x1b[32mINFO\x1b[0m | httpx                | _send_single_request:1025 | HTTP Request: POST https://api.openai.com/v1/chat/completions "HTTP/1.1 200 OK"\r\n2025-09-05 15:43:08 | \x1b[32mINFO\x1b[0m | httpx                | _send_single_request:1025 | HTTP Request: POST https://api.openai.com/v1/chat/completions "HTTP/1.1 200 OK"\r\n2025-09-05 15:43:09 | \x1b[32mINFO\x1b[0m | httpx                | _send_single_request:1025 | HTTP Request: POST https://api.openai.com/v1/chat/completions "HTTP/1.1 200 OK"\r\n2025-09-05 15:43:10 | \x1b[32mINFO\x1b[0m | __main__             | <module>       :113  | Supervisor processing completed in 7.19 seconds\r\n2025-09-05 15:43:10 | \x1b[32mINFO\x1b[0m | __main__             | <module>       :117  | Final response generated: It appears there are still required details missing for your patient registration. I\x92ll need to clar...\r\n2025-09-05 15:43:10 | \x1b[32mINFO\x1b[0m | __main__             | <module>       :131  | Conversation history updated successfully\r\n2025-09-05 15:43:10 | \x1b[32mINFO\x1b[0m | __main__             | <module>       :163  | Loading system statistics\r\n2025-09-05 15:43:10 | \x1b[31mERROR\x1b[0m | __main__             | <module>       :197  | Error loading statistics: No columns to parse from file\r\nTraceback (most recent call last):\r\n  File "C:\\Users\\Aman\\Documents\\Scheduling-System\\ai-scheduling-agent\\app.py", line 167, in <module>\r\n    patients_df = pd.read_csv(DATA_CONFIG["patients_file"])\r\n  File "C:\\Users\\Aman\\Documents\\Scheduling-System\\ai-scheduling-agent\\.venv\\Lib\\site-packages\\pandas\\io\\parsers\\readers.py", line 1026, in read_csv\r\n    return _read(filepath_or_buffer, kwds)\r\n  File "C:\\Users\\Aman\\Documents\\Scheduling-System\\ai-scheduling-agent\\.venv\\Lib\\site-packages\\pandas\\io\\parsers\\readers.py", line 620, in _read\r\n    parser = TextFileReader(filepath_or_buffer, **kwds)\r\n  File "C:\\Users\\Aman\\Documents\\Scheduling-System\\ai-scheduling-agent\\.venv\\Lib\\site-packages\\pandas\\io\\parsers\\readers.py", line 1620, in __init__\r\n    self._engine = self._make_engine(f, self.engine)\r\n                   ~~~~~~~~~~~~~~~~~^^^^^^^^^^^^^^^^\r\n  File "C:\\Users\\Aman\\Documents\\Scheduling-System\\ai-scheduling-agent\\.venv\\Lib\\site-packages\\pandas\\io\\parsers\\readers.py", line 1898, in _make_engine\r\n    return mapping[engine](f, **self.options)\r\n           ~~~~~~~~~~~~~~~^^^^^^^^^^^^^^^^^^^\r\n  File "C:\\Users\\Aman\\Documents\\Scheduling-System\\ai-scheduling-agent\\.venv\\Lib\\site-packages\\pandas\\io\\parsers\\c_parser_wrapper.py", line 93, in __init__\r\n    self._reader = parsers.TextReader(src, **kwds)\r\n                   ~~~~~~~~~~~~~~~~~~^^^^^^^^^^^^^\r\n  File "pandas/_libs/parsers.pyx", line 581, in pandas._libs.parsers.TextReader.__cinit__\r\npandas.errors.EmptyDataError: No columns to parse from file\r\n2025-09-05 15:43:10 | \x1b[31mERROR\x1b[0m | __main__             | <module>       :240  | Error reading logs: \'utf-8\' codec can\'t decode byte 0x92 in position 2943: invalid start byte\r\nTraceback (most recent call last):\r\n  File "C:\\Users\\Aman\\Documents\\Scheduling-System\\ai-scheduling-agent\\app.py", line 221, in <module>\r\n    lines = f.readlines()\r\n  File "<frozen codecs>", line 325, in decode\r\nUnicodeDecodeError: \'utf-8\' codec can\'t decode byte 0x92 in position 2943: invalid start byte\r\n2025-09-05 15:43:31 | \x1b[32mINFO\x1b[0m | __main__             | <module>       :24   | Initializing Streamlit application\r\n2025-09-05 15:43:31 | \x1b[32mINFO\x1b[0m | __main__             | <module>       :83   | User input received: book the appointment...\r\n2025-09-05 15:43:31 | \x1b[32mINFO\x1b[0m | __main__             | log_agent_operation:195  | Operation: user_input | Details: {\r\n  "prompt": "book the appointment",\r\n  "thread_id": "8a99098e-20af-4748-8c64-b9548a9f8499",\r\n  "timestamp": "2025-09-05T15:43:31.237753"\r\n}\r\n2025-09-05 15:43:31 | \x1b[32mINFO\x1b[0m | __main__             | <module>       :99   | Starting supervisor agent processing\r\n2025-09-05 15:43:33 | \x1b[32mINFO\x1b[0m | httpx                | _send_single_request:1025 | HTTP Request: POST https://api.openai.com/v1/chat/completions "HTTP/1.1 200 OK"\r\n2025-09-05 15:43:34 | \x1b[32mINFO\x1b[0m | httpx                | _send_single_request:1025 | HTTP Request: POST https://api.openai.com/v1/chat/completions "HTTP/1.1 200 OK"\r\n2025-09-05 15:43:36 | \x1b[32mINFO\x1b[0m | httpx                | _send_single_request:1025 | HTTP Request: POST https://api.openai.com/v1/chat/completions "HTTP/1.1 200 OK"\r\n2025-09-05 15:43:36 | \x1b[32mINFO\x1b[0m | __main__             | <module>       :113  | Supervisor processing completed in 5.05 seconds\r\n2025-09-05 15:43:36 | \x1b[32mINFO\x1b[0m | __main__             | <module>       :117  | Final response generated: Could you please let me know if you have a preferred doctor or a preferred date and time for your ap...\r\n2025-09-05 15:43:36 | \x1b[32mINFO\x1b[0m | __main__             | <module>       :131  | Conversation history updated successfully\r\n2025-09-05 15:43:36 | \x1b[32mINFO\x1b[0m | __main__             | <module>       :163  | Loading system statistics\r\n2025-09-05 15:43:36 | \x1b[31mERROR\x1b[0m | __main__             | <module>       :197  | Error loading statistics: No columns to parse from file\r\nTraceback (most recent call last):\r\n  File "C:\\Users\\Aman\\Documents\\Scheduling-System\\ai-scheduling-agent\\app.py", line 167, in <module>\r\n    patients_df = pd.read_csv(DATA_CONFIG["patients_file"])\r\n  File "C:\\Users\\Aman\\Documents\\Scheduling-System\\ai-scheduling-agent\\.venv\\Lib\\site-packages\\pandas\\io\\parsers\\readers.py", line 1026, in read_csv\r\n    return _read(filepath_or_buffer, kwds)\r\n  File "C:\\Users\\Aman\\Documents\\Scheduling-System\\ai-scheduling-agent\\.venv\\Lib\\site-packages\\pandas\\io\\parsers\\readers.py", line 620, in _read\r\n    parser = TextFileReader(filepath_or_buffer, **kwds)\r\n  File "C:\\Users\\Aman\\Documents\\Scheduling-System\\ai-scheduling-agent\\.venv\\Lib\\site-packages\\pandas\\io\\parsers\\readers.py", line 1620, in __init__\r\n    self._engine = self._make_engine(f, self.engine)\r\n                   ~~~~~~~~~~~~~~~~~^^^^^^^^^^^^^^^^\r\n  File "C:\\Users\\Aman\\Documents\\Scheduling-System\\ai-scheduling-agent\\.venv\\Lib\\site-packages\\pandas\\io\\parsers\\readers.py", ', 2943, 2944, 'invalid start byte'), <traceback object at 0x0000024BF4066D00>)
Traceback (most recent call last):
  File "C:\Users\Aman\Documents\Scheduling-System\ai-scheduling-agent\app.py", line 221, in <module>
    lines = f.readlines()
  File "<frozen codecs>", line 325, in decode
UnicodeDecodeError: 'utf-8' codec can't decode byte 0x92 in position 2943: invalid start byte
2025-09-05 15:53:03 | [31mERROR[0m | __main__             | <module>       :240  | Error reading logs: 'utf-8' codec can't decode byte 0x92 in position 2943: invalid start byte
C:\Users\Aman\Documents\Scheduling-System\ai-scheduling-agent\app.py:240
(<class 'UnicodeDecodeError'>, UnicodeDecodeError('utf-8', b'ers\\readers.py", line 1026, in read_csv\r\n    return _read(filepath_or_buffer, kwds)\r\n  File "C:\\Users\\Aman\\Documents\\Scheduling-System\\ai-scheduling-agent\\.venv\\Lib\\site-packages\\pandas\\io\\parsers\\readers.py", line 620, in _read\r\n    parser = TextFileReader(filepath_or_buffer, **kwds)\r\n  File "C:\\Users\\Aman\\Documents\\Scheduling-System\\ai-scheduling-agent\\.venv\\Lib\\site-packages\\pandas\\io\\parsers\\readers.py", line 1620, in __init__\r\n    self._engine = self._make_engine(f, self.engine)\r\n                   ~~~~~~~~~~~~~~~~~^^^^^^^^^^^^^^^^\r\n  File "C:\\Users\\Aman\\Documents\\Scheduling-System\\ai-scheduling-agent\\.venv\\Lib\\site-packages\\pandas\\io\\parsers\\readers.py", line 1898, in _make_engine\r\n    return mapping[engine](f, **self.options)\r\n           ~~~~~~~~~~~~~~~^^^^^^^^^^^^^^^^^^^\r\n  File "C:\\Users\\Aman\\Documents\\Scheduling-System\\ai-scheduling-agent\\.venv\\Lib\\site-packages\\pandas\\io\\parsers\\c_parser_wrapper.py", line 93, in __init__\r\n    self._reader = parsers.TextReader(src, **kwds)\r\n                   ~~~~~~~~~~~~~~~~~~^^^^^^^^^^^^^\r\n  File "pandas/_libs/parsers.pyx", line 581, in pandas._libs.parsers.TextReader.__cinit__\r\npandas.errors.EmptyDataError: No columns to parse from file\r\n2025-09-05 15:43:02 | \x1b[32mINFO\x1b[0m | __main__             | <module>       :24   | Initializing Streamlit application\r\n2025-09-05 15:43:02 | \x1b[32mINFO\x1b[0m | __main__             | <module>       :83   | User input received: gender: male, emergency name: Aditya, emergency contact: 8779500293 ...\r\n2025-09-05 15:43:02 | \x1b[32mINFO\x1b[0m | __main__             | log_agent_operation:195  | Operation: user_input | Details: {\r\n  "prompt": "gender: male, emergency name: Aditya, emergency contact: 8779500293 ",\r\n  "thread_id": "8a99098e-20af-4748-8c64-b9548a9f8499",\r\n  "timestamp": "2025-09-05T15:43:02.820339"\r\n}\r\n2025-09-05 15:43:02 | \x1b[32mINFO\x1b[0m | __main__             | <module>       :99   | Starting supervisor agent processing\r\n2025-09-05 15:43:05 | \x1b[32mINFO\x1b[0m | httpx                | _send_single_request:1025 | HTTP Request: POST https://api.openai.com/v1/chat/completions "HTTP/1.1 200 OK"\r\n2025-09-05 15:43:06 | \x1b[32mINFO\x1b[0m | httpx                | _send_single_request:1025 | HTTP Request: POST https://api.openai.com/v1/chat/completions "HTTP/1.1 200 OK"\r\n2025-09-05 15:43:08 | \x1b[32mINFO\x1b[0m | httpx                | _send_single_request:1025 | HTTP Request: POST https://api.openai.com/v1/chat/completions "HTTP/1.1 200 OK"\r\n2025-09-05 15:43:09 | \x1b[32mINFO\x1b[0m | httpx                | _send_single_request:1025 | HTTP Request: POST https://api.openai.com/v1/chat/completions "HTTP/1.1 200 OK"\r\n2025-09-05 15:43:10 | \x1b[32mINFO\x1b[0m | __main__             | <module>       :113  | Supervisor processing completed in 7.19 seconds\r\n2025-09-05 15:43:10 | \x1b[32mINFO\x1b[0m | __main__             | <module>       :117  | Final response generated: It appears there are still required details missing for your patient registration. I\x92ll need to clar...\r\n2025-09-05 15:43:10 | \x1b[32mINFO\x1b[0m | __main__             | <module>       :131  | Conversation history updated successfully\r\n2025-09-05 15:43:10 | \x1b[32mINFO\x1b[0m | __main__             | <module>       :163  | Loading system statistics\r\n2025-09-05 15:43:10 | \x1b[31mERROR\x1b[0m | __main__             | <module>       :197  | Error loading statistics: No columns to parse from file\r\nTraceback (most recent call last):\r\n  File "C:\\Users\\Aman\\Documents\\Scheduling-System\\ai-scheduling-agent\\app.py", line 167, in <module>\r\n    patients_df = pd.read_csv(DATA_CONFIG["patients_file"])\r\n  File "C:\\Users\\Aman\\Documents\\Scheduling-System\\ai-scheduling-agent\\.venv\\Lib\\site-packages\\pandas\\io\\parsers\\readers.py", line 1026, in read_csv\r\n    return _read(filepath_or_buffer, kwds)\r\n  File "C:\\Users\\Aman\\Documents\\Scheduling-System\\ai-scheduling-agent\\.venv\\Lib\\site-packages\\pandas\\io\\parsers\\readers.py", line 620, in _read\r\n    parser = TextFileReader(filepath_or_buffer, **kwds)\r\n  File "C:\\Users\\Aman\\Documents\\Scheduling-System\\ai-scheduling-agent\\.venv\\Lib\\site-packages\\pandas\\io\\parsers\\readers.py", line 1620, in __init__\r\n    self._engine = self._make_engine(f, self.engine)\r\n                   ~~~~~~~~~~~~~~~~~^^^^^^^^^^^^^^^^\r\n  File "C:\\Users\\Aman\\Documents\\Scheduling-System\\ai-scheduling-agent\\.venv\\Lib\\site-packages\\pandas\\io\\parsers\\readers.py", line 1898, in _make_engine\r\n    return mapping[engine](f, **self.options)\r\n           ~~~~~~~~~~~~~~~^^^^^^^^^^^^^^^^^^^\r\n  File "C:\\Users\\Aman\\Documents\\Scheduling-System\\ai-scheduling-agent\\.venv\\Lib\\site-packages\\pandas\\io\\parsers\\c_parser_wrapper.py", line 93, in __init__\r\n    self._reader = parsers.TextReader(src, **kwds)\r\n                   ~~~~~~~~~~~~~~~~~~^^^^^^^^^^^^^\r\n  File "pandas/_libs/parsers.pyx", line 581, in pandas._libs.parsers.TextReader.__cinit__\r\npandas.errors.EmptyDataError: No columns to parse from file\r\n2025-09-05 15:43:10 | \x1b[31mERROR\x1b[0m | __main__             | <module>       :240  | Error reading logs: \'utf-8\' codec can\'t decode byte 0x92 in position 2943: invalid start byte\r\nTraceback (most recent call last):\r\n  File "C:\\Users\\Aman\\Documents\\Scheduling-System\\ai-scheduling-agent\\app.py", line 221, in <module>\r\n    lines = f.readlines()\r\n  File "<frozen codecs>", line 325, in decode\r\nUnicodeDecodeError: \'utf-8\' codec can\'t decode byte 0x92 in position 2943: invalid start byte\r\n2025-09-05 15:43:31 | \x1b[32mINFO\x1b[0m | __main__             | <module>       :24   | Initializing Streamlit application\r\n2025-09-05 15:43:31 | \x1b[32mINFO\x1b[0m | __main__             | <module>       :83   | User input received: book the appointment...\r\n2025-09-05 15:43:31 | \x1b[32mINFO\x1b[0m | __main__             | log_agent_operation:195  | Operation: user_input | Details: {\r\n  "prompt": "book the appointment",\r\n  "thread_id": "8a99098e-20af-4748-8c64-b9548a9f8499",\r\n  "timestamp": "2025-09-05T15:43:31.237753"\r\n}\r\n2025-09-05 15:43:31 | \x1b[32mINFO\x1b[0m | __main__             | <module>       :99   | Starting supervisor agent processing\r\n2025-09-05 15:43:33 | \x1b[32mINFO\x1b[0m | httpx                | _send_single_request:1025 | HTTP Request: POST https://api.openai.com/v1/chat/completions "HTTP/1.1 200 OK"\r\n2025-09-05 15:43:34 | \x1b[32mINFO\x1b[0m | httpx                | _send_single_request:1025 | HTTP Request: POST https://api.openai.com/v1/chat/completions "HTTP/1.1 200 OK"\r\n2025-09-05 15:43:36 | \x1b[32mINFO\x1b[0m | httpx                | _send_single_request:1025 | HTTP Request: POST https://api.openai.com/v1/chat/completions "HTTP/1.1 200 OK"\r\n2025-09-05 15:43:36 | \x1b[32mINFO\x1b[0m | __main__             | <module>       :113  | Supervisor processing completed in 5.05 seconds\r\n2025-09-05 15:43:36 | \x1b[32mINFO\x1b[0m | __main__             | <module>       :117  | Final response generated: Could you please let me know if you have a preferred doctor or a preferred date and time for your ap...\r\n2025-09-05 15:43:36 | \x1b[32mINFO\x1b[0m | __main__             | <module>       :131  | Conversation history updated successfully\r\n2025-09-05 15:43:36 | \x1b[32mINFO\x1b[0m | __main__             | <module>       :163  | Loading system statistics\r\n2025-09-05 15:43:36 | \x1b[31mERROR\x1b[0m | __main__             | <module>       :197  | Error loading statistics: No columns to parse from file\r\nTraceback (most recent call last):\r\n  File "C:\\Users\\Aman\\Documents\\Scheduling-System\\ai-scheduling-agent\\app.py", line 167, in <module>\r\n    patients_df = pd.read_csv(DATA_CONFIG["patients_file"])\r\n  File "C:\\Users\\Aman\\Documents\\Scheduling-System\\ai-scheduling-agent\\.venv\\Lib\\site-packages\\pandas\\io\\parsers\\readers.py", line 1026, in read_csv\r\n    return _read(filepath_or_buffer, kwds)\r\n  File "C:\\Users\\Aman\\Documents\\Scheduling-System\\ai-scheduling-agent\\.venv\\Lib\\site-packages\\pandas\\io\\parsers\\readers.py", line 620, in _read\r\n    parser = TextFileReader(filepath_or_buffer, **kwds)\r\n  File "C:\\Users\\Aman\\Documents\\Scheduling-System\\ai-scheduling-agent\\.venv\\Lib\\site-packages\\pandas\\io\\parsers\\readers.py", line 1620, in __init__\r\n    self._engine = self._make_engine(f, self.engine)\r\n                   ~~~~~~~~~~~~~~~~~^^^^^^^^^^^^^^^^\r\n  File "C:\\Users\\Aman\\Documents\\Scheduling-System\\ai-scheduling-agent\\.venv\\Lib\\site-packages\\pandas\\io\\parsers\\readers.py", ', 2943, 2944, 'invalid start byte'), <traceback object at 0x0000024BF27D8440>)
Traceback (most recent call last):
  File "C:\Users\Aman\Documents\Scheduling-System\ai-scheduling-agent\app.py", line 221, in <module>
    lines = f.readlines()
  File "<frozen codecs>", line 325, in decode
UnicodeDecodeError: 'utf-8' codec can't decode byte 0x92 in position 2943: invalid start byte
2025-09-05 15:53:25 | [31mERROR[0m | __main__             | <module>       :240  | Error reading logs: 'utf-8' codec can't decode byte 0x92 in position 2943: invalid start byte
C:\Users\Aman\Documents\Scheduling-System\ai-scheduling-agent\app.py:240
(<class 'UnicodeDecodeError'>, UnicodeDecodeError('utf-8', b'ers\\readers.py", line 1026, in read_csv\r\n    return _read(filepath_or_buffer, kwds)\r\n  File "C:\\Users\\Aman\\Documents\\Scheduling-System\\ai-scheduling-agent\\.venv\\Lib\\site-packages\\pandas\\io\\parsers\\readers.py", line 620, in _read\r\n    parser = TextFileReader(filepath_or_buffer, **kwds)\r\n  File "C:\\Users\\Aman\\Documents\\Scheduling-System\\ai-scheduling-agent\\.venv\\Lib\\site-packages\\pandas\\io\\parsers\\readers.py", line 1620, in __init__\r\n    self._engine = self._make_engine(f, self.engine)\r\n                   ~~~~~~~~~~~~~~~~~^^^^^^^^^^^^^^^^\r\n  File "C:\\Users\\Aman\\Documents\\Scheduling-System\\ai-scheduling-agent\\.venv\\Lib\\site-packages\\pandas\\io\\parsers\\readers.py", line 1898, in _make_engine\r\n    return mapping[engine](f, **self.options)\r\n           ~~~~~~~~~~~~~~~^^^^^^^^^^^^^^^^^^^\r\n  File "C:\\Users\\Aman\\Documents\\Scheduling-System\\ai-scheduling-agent\\.venv\\Lib\\site-packages\\pandas\\io\\parsers\\c_parser_wrapper.py", line 93, in __init__\r\n    self._reader = parsers.TextReader(src, **kwds)\r\n                   ~~~~~~~~~~~~~~~~~~^^^^^^^^^^^^^\r\n  File "pandas/_libs/parsers.pyx", line 581, in pandas._libs.parsers.TextReader.__cinit__\r\npandas.errors.EmptyDataError: No columns to parse from file\r\n2025-09-05 15:43:02 | \x1b[32mINFO\x1b[0m | __main__             | <module>       :24   | Initializing Streamlit application\r\n2025-09-05 15:43:02 | \x1b[32mINFO\x1b[0m | __main__             | <module>       :83   | User input received: gender: male, emergency name: Aditya, emergency contact: 8779500293 ...\r\n2025-09-05 15:43:02 | \x1b[32mINFO\x1b[0m | __main__             | log_agent_operation:195  | Operation: user_input | Details: {\r\n  "prompt": "gender: male, emergency name: Aditya, emergency contact: 8779500293 ",\r\n  "thread_id": "8a99098e-20af-4748-8c64-b9548a9f8499",\r\n  "timestamp": "2025-09-05T15:43:02.820339"\r\n}\r\n2025-09-05 15:43:02 | \x1b[32mINFO\x1b[0m | __main__             | <module>       :99   | Starting supervisor agent processing\r\n2025-09-05 15:43:05 | \x1b[32mINFO\x1b[0m | httpx                | _send_single_request:1025 | HTTP Request: POST https://api.openai.com/v1/chat/completions "HTTP/1.1 200 OK"\r\n2025-09-05 15:43:06 | \x1b[32mINFO\x1b[0m | httpx                | _send_single_request:1025 | HTTP Request: POST https://api.openai.com/v1/chat/completions "HTTP/1.1 200 OK"\r\n2025-09-05 15:43:08 | \x1b[32mINFO\x1b[0m | httpx                | _send_single_request:1025 | HTTP Request: POST https://api.openai.com/v1/chat/completions "HTTP/1.1 200 OK"\r\n2025-09-05 15:43:09 | \x1b[32mINFO\x1b[0m | httpx                | _send_single_request:1025 | HTTP Request: POST https://api.openai.com/v1/chat/completions "HTTP/1.1 200 OK"\r\n2025-09-05 15:43:10 | \x1b[32mINFO\x1b[0m | __main__             | <module>       :113  | Supervisor processing completed in 7.19 seconds\r\n2025-09-05 15:43:10 | \x1b[32mINFO\x1b[0m | __main__             | <module>       :117  | Final response generated: It appears there are still required details missing for your patient registration. I\x92ll need to clar...\r\n2025-09-05 15:43:10 | \x1b[32mINFO\x1b[0m | __main__             | <module>       :131  | Conversation history updated successfully\r\n2025-09-05 15:43:10 | \x1b[32mINFO\x1b[0m | __main__             | <module>       :163  | Loading system statistics\r\n2025-09-05 15:43:10 | \x1b[31mERROR\x1b[0m | __main__             | <module>       :197  | Error loading statistics: No columns to parse from file\r\nTraceback (most recent call last):\r\n  File "C:\\Users\\Aman\\Documents\\Scheduling-System\\ai-scheduling-agent\\app.py", line 167, in <module>\r\n    patients_df = pd.read_csv(DATA_CONFIG["patients_file"])\r\n  File "C:\\Users\\Aman\\Documents\\Scheduling-System\\ai-scheduling-agent\\.venv\\Lib\\site-packages\\pandas\\io\\parsers\\readers.py", line 1026, in read_csv\r\n    return _read(filepath_or_buffer, kwds)\r\n  File "C:\\Users\\Aman\\Documents\\Scheduling-System\\ai-scheduling-agent\\.venv\\Lib\\site-packages\\pandas\\io\\parsers\\readers.py", line 620, in _read\r\n    parser = TextFileReader(filepath_or_buffer, **kwds)\r\n  File "C:\\Users\\Aman\\Documents\\Scheduling-System\\ai-scheduling-agent\\.venv\\Lib\\site-packages\\pandas\\io\\parsers\\readers.py", line 1620, in __init__\r\n    self._engine = self._make_engine(f, self.engine)\r\n                   ~~~~~~~~~~~~~~~~~^^^^^^^^^^^^^^^^\r\n  File "C:\\Users\\Aman\\Documents\\Scheduling-System\\ai-scheduling-agent\\.venv\\Lib\\site-packages\\pandas\\io\\parsers\\readers.py", line 1898, in _make_engine\r\n    return mapping[engine](f, **self.options)\r\n           ~~~~~~~~~~~~~~~^^^^^^^^^^^^^^^^^^^\r\n  File "C:\\Users\\Aman\\Documents\\Scheduling-System\\ai-scheduling-agent\\.venv\\Lib\\site-packages\\pandas\\io\\parsers\\c_parser_wrapper.py", line 93, in __init__\r\n    self._reader = parsers.TextReader(src, **kwds)\r\n                   ~~~~~~~~~~~~~~~~~~^^^^^^^^^^^^^\r\n  File "pandas/_libs/parsers.pyx", line 581, in pandas._libs.parsers.TextReader.__cinit__\r\npandas.errors.EmptyDataError: No columns to parse from file\r\n2025-09-05 15:43:10 | \x1b[31mERROR\x1b[0m | __main__             | <module>       :240  | Error reading logs: \'utf-8\' codec can\'t decode byte 0x92 in position 2943: invalid start byte\r\nTraceback (most recent call last):\r\n  File "C:\\Users\\Aman\\Documents\\Scheduling-System\\ai-scheduling-agent\\app.py", line 221, in <module>\r\n    lines = f.readlines()\r\n  File "<frozen codecs>", line 325, in decode\r\nUnicodeDecodeError: \'utf-8\' codec can\'t decode byte 0x92 in position 2943: invalid start byte\r\n2025-09-05 15:43:31 | \x1b[32mINFO\x1b[0m | __main__             | <module>       :24   | Initializing Streamlit application\r\n2025-09-05 15:43:31 | \x1b[32mINFO\x1b[0m | __main__             | <module>       :83   | User input received: book the appointment...\r\n2025-09-05 15:43:31 | \x1b[32mINFO\x1b[0m | __main__             | log_agent_operation:195  | Operation: user_input | Details: {\r\n  "prompt": "book the appointment",\r\n  "thread_id": "8a99098e-20af-4748-8c64-b9548a9f8499",\r\n  "timestamp": "2025-09-05T15:43:31.237753"\r\n}\r\n2025-09-05 15:43:31 | \x1b[32mINFO\x1b[0m | __main__             | <module>       :99   | Starting supervisor agent processing\r\n2025-09-05 15:43:33 | \x1b[32mINFO\x1b[0m | httpx                | _send_single_request:1025 | HTTP Request: POST https://api.openai.com/v1/chat/completions "HTTP/1.1 200 OK"\r\n2025-09-05 15:43:34 | \x1b[32mINFO\x1b[0m | httpx                | _send_single_request:1025 | HTTP Request: POST https://api.openai.com/v1/chat/completions "HTTP/1.1 200 OK"\r\n2025-09-05 15:43:36 | \x1b[32mINFO\x1b[0m | httpx                | _send_single_request:1025 | HTTP Request: POST https://api.openai.com/v1/chat/completions "HTTP/1.1 200 OK"\r\n2025-09-05 15:43:36 | \x1b[32mINFO\x1b[0m | __main__             | <module>       :113  | Supervisor processing completed in 5.05 seconds\r\n2025-09-05 15:43:36 | \x1b[32mINFO\x1b[0m | __main__             | <module>       :117  | Final response generated: Could you please let me know if you have a preferred doctor or a preferred date and time for your ap...\r\n2025-09-05 15:43:36 | \x1b[32mINFO\x1b[0m | __main__             | <module>       :131  | Conversation history updated successfully\r\n2025-09-05 15:43:36 | \x1b[32mINFO\x1b[0m | __main__             | <module>       :163  | Loading system statistics\r\n2025-09-05 15:43:36 | \x1b[31mERROR\x1b[0m | __main__             | <module>       :197  | Error loading statistics: No columns to parse from file\r\nTraceback (most recent call last):\r\n  File "C:\\Users\\Aman\\Documents\\Scheduling-System\\ai-scheduling-agent\\app.py", line 167, in <module>\r\n    patients_df = pd.read_csv(DATA_CONFIG["patients_file"])\r\n  File "C:\\Users\\Aman\\Documents\\Scheduling-System\\ai-scheduling-agent\\.venv\\Lib\\site-packages\\pandas\\io\\parsers\\readers.py", line 1026, in read_csv\r\n    return _read(filepath_or_buffer, kwds)\r\n  File "C:\\Users\\Aman\\Documents\\Scheduling-System\\ai-scheduling-agent\\.venv\\Lib\\site-packages\\pandas\\io\\parsers\\readers.py", line 620, in _read\r\n    parser = TextFileReader(filepath_or_buffer, **kwds)\r\n  File "C:\\Users\\Aman\\Documents\\Scheduling-System\\ai-scheduling-agent\\.venv\\Lib\\site-packages\\pandas\\io\\parsers\\readers.py", line 1620, in __init__\r\n    self._engine = self._make_engine(f, self.engine)\r\n                   ~~~~~~~~~~~~~~~~~^^^^^^^^^^^^^^^^\r\n  File "C:\\Users\\Aman\\Documents\\Scheduling-System\\ai-scheduling-agent\\.venv\\Lib\\site-packages\\pandas\\io\\parsers\\readers.py", ', 2943, 2944, 'invalid start byte'), <traceback object at 0x0000024BF40781C0>)
Traceback (most recent call last):
  File "C:\Users\Aman\Documents\Scheduling-System\ai-scheduling-agent\app.py", line 221, in <module>
    lines = f.readlines()
  File "<frozen codecs>", line 325, in decode
UnicodeDecodeError: 'utf-8' codec can't decode byte 0x92 in position 2943: invalid start byte
2025-09-05 16:29:58 | [31mERROR[0m | __main__             | test_basic_logging:25   | This is an error message
C:\Users\Aman\Documents\Scheduling-System\ai-scheduling-agent\test_logging.py:25
None
2025-09-05 16:31:47 | [31mERROR[0m | __main__             | test_basic_logging:25   | This is an error message
C:\Users\Aman\Documents\Scheduling-System\ai-scheduling-agent\test_logging.py:25
None
